Workbook
Name a: #REF!
Name Comprobantes: '[1]Tabla de Comprobantes'!$A$3:$A$65
Name Fletes_MX: Fletes!$A$1:$G$18
Name Fletes_Tab: Fletes!$A$5:$G$17
Name Mobiliario: Fletes!$I$6:$I$19
Name PC: '[1]Tabla de Comprobantes'!$E$3:$E$14
Name Proveedores: Proveedores!$A$2:$D$32
Name ProveedoreS_TC: Proveedores!$A$2:$E$32
Name Taba_Region: Fletes!$G$5:$G$18
Name Tabla_Costos: Fletes!$D$5:$F$18
Name Tabla_Fletes: Fletes!$I$6:$K$19
Name Tabla_Instalacion: Fletes!$M$6:$N$19
Name Tabla_Proveedores: Proveedores!$A$29:$B$37
Name Tabla_Proveedores_1: Proveedores!$A$2:$B$32

Sheet Cotizacion
A3: COTIZACION # | B3: 400-19383
A4: =TODAY() -> 46163
A7: PROYECTO:
A8: Nombre:
A9: Correo:
A10: Telefono:
A11: Direccion:
A12: Razon Social:
A15: CÓDIGO | B15: IMAGEN | C15: DESCRIPCIÓN | D15: MEDIDAS | E15: CANT. | F15: P. UNIT | G15: % DESC. | H15: DESCUENTO | I15: SUBTOTAL | J15: TOTAL
E17: 0 | G17: 0 | H17: =F17*G17 -> 0 | I17: =F17-H17 -> 0 | J17: =E17*I17 -> 0 | L17: =1400/5 -> 280 | O17: 483441.6 | P17: =O17*3% -> 14503.248
G18: 0 | H18: =F18*G18 -> 0 | I18: =F18-H18 -> 0 | J18: =E18*I18 -> 0 | P18: 19774
G19: 0 | H19: =F19*G19 -> 0 | I19: =F19-H19 -> 0 | J19: =E19*I19 -> 0 | P19: =SUM(P17:P18) -> 34277.248
G20: 0 | H20: =F20*G20 -> 0 | I20: =F20-H20 -> 0 | J20: =E20*I20 -> 0
D21: SUBTOTAL: | H21: {=SUM(IFERROR(J17:J20,0))} -> 0
D22: COSTO DE FLETE: | H22: =H21*10% -> 0 | P22: =#REF!-P19 -> #REF!
D23: SUBTOTAL: | H23: =H21+H22 -> 0
D24: IVA: | H24: =H23*16% -> 0
D25: TOTAL: | H25: =H23+H24 -> 0
A29: SHOWROOM Av. México No. 2501, Vallarta Norte, C.P. 44690, Guadalajara Jal | D29: WWW.MOBILITI.MX
A32: CONDICIONES
A33: 1) CONDICIONES COMERCIALES
A34: a. Esta cotización se encuentra en Dolares estadonidenses USD . En caso de que el pago se efectúe en una moneda diferente a la de este documento, se tomará como referencia el tipo de cambio bancario.
A35: b. Las cantidades mencionadas en esta cotización están calculadas sobre las tarifas arancelarias que se encuentran vigentes a la fecha de este documento. Dichas cantidades están sujetas a cambio conforme a actualizaciones que pueda haber en dichas tarifas.
A36: c. Los precios otorgados están basados en la compra del proyecto completo y la entrega en una sola etapa. En caso de requerir más de una entrega o las cantidades o artículos de esta cotización sean cambiados, los precios y descuentos mencionados anteriormente pueden variar.
A37: d. Las condiciones de pago son: 1- Pago 60% Anticipo + 20% Contra Aviso de Embarque + 20% Contra Entrega.
A38: e. En caso de que no se cumplan las condiciones de pago anteriormente mencionadas, se cobrará el 3% sobre el saldo total de esta cotización por cada mes de atraso o fracción.
A39: f. En caso de que, por motivos ajenos a Espacios Corporativos y de Diseño Jofe, SA de CV, no pueda ser entregado el producto de un proyecto, esto no limita el cobro del mismo. En el caso de que se entreguen dañados uno o más productos o componentes de los mismos, por transporte, manejo, instalación, defecto de fábrica, o bien por error de especificación imputable a nuestros representantes, se procederá a reparar dichos daños o a solicitar sus reposiciones. Sin embargo, esto no será motivo de retención de pago, únicamente podrá quedar pendiente el monto correspondiente al valor de esos productos y/o partes dañadas o faltantes.
A41: 2) PLAZO DE ENTREGA
A42: a. El plazo de entrega, en sitio, del producto mencionado en esta cotización es de 12 Semanas habiles despues de recibir anticipo y cotizacion firmada de Vobo con terminados Según Existencias
A43: b. Para que Espacios Corporativos y de Diseño Jofe, SA de CV, procese un pedido, se requieren del cliente los siguientes documentos firmados: orden de compra oficial o contrato, planos del layout (si aplica), presentación (si aplica), cotización con acabados definidos por el cliente, políticas de garantías y que se cumplan las condiciones de pago iniciales.
A44: c. Los plazos de entrega de nuestros productos dependen del volumen de producción de las plantas de fabricación, es por esto que pueden variar sin previo aviso.
... A73: c. Al recibir los documentos mencionados en el inciso 2-b, queda entendido que el cliente acepta incondicionalmente las presentes condiciones de venta y garantías. Renunciando este a cualquier tipo de reclamo que no esté estipulado en este documento.
A77: NOMBRE, FIRMA Y FECHA DE AUTORIZACIÓN DEL CLIENTE | D77: NOMBRE DE EJECUTIVO DE VENTAS
L122: =IF(ROUND(#REF!,2)=ROUND('Estrategia Comercial '!B69,2),"ESTRATEGIA CORRECTA","REVISA TU ESTRATEGIA") -> #REF!

Sheet sheep
A1: Price List
A3: Price to： | I3: contact： | J3: Lynn li
A4: Trade term: | C4: FOB GUANGZHOU PORT | I4: Submitted date： | J4: 46141
A5: address： | I5: Email | J5: lynnli@mexytech.com
A7: No. | B7: Series | C7: Name | D7: Photo | F7: Length/m | G7: Unit | H7: Price | I7: Total money | J7: Note | K7: ramon price with 10% commision
A8: 6 | B8: wpc | C8: 600V slot Bpanel | F8: 600*9*2950 | G8: sqm | H8: 4.774 | K8: =H8*1.1 -> 5.2514
A9: 7 | B9: wpc | C9: 160 slat panel | F9: 160*22*2900 | G9: sqm | H9: 7.29 | K9: =H9*1.1 -> 8.019
A10: 1 | B10: perfil aluminum | C10: 10cm shape duplex Thickness around 0.9 | F10: 3 | G10: meter | H10: 0.781 | K10: =H10*1.1 -> 0.8591
A11: 2 | B11: perfil aluminum | C11: 9cm shape closure Thickness around 0.6 | F11: 3 | G11: meter | H11: 0.671 | K11: =H11*1.1 -> 0.7381
A12: 3 | B12: perfil aluminum | C12: 9cm shape duplex Thickness around 0.9 | F12: 3 | G12: meter | H12: 0.891 | K12: =H12*1.1 -> 0.9801
A13: 4 | B13: perfil aluminum | C13: 9cm I-shaped light strip (including lampshade) Thickness around 0.6 | F13: 3 | G13: meter | H13: 1.001 | K13: =H13*1.1 -> 1.1011
A14: 5 | B14: perfil aluminum | C14: 9 centimeter pointed yang angle Thickness around 0.85 | F14: 3 | G14: meter | H14: 1.023 | K14: =H14*1.1 -> 1.1253
A15: 8 | B15: perfil aluminum | C15: 10cm shape I-beam Thickness around 0.6 | F15: 3 | G15: meter | H15: 0.561 | K15: =H15*1.1 -> 0.6171
A16: 9 | B16: perfil aluminum | C16: 10cm shape closure Thickness around 0.6 | F16: 3 | G16: meter | H16: 0.561 | K16: =H16*1.1 -> 0.6171
A17: 10 | B17: perfil aluminum | C17: 10cm shape duplex Thickness around 0.9 | F17: 3 | G17: meter | H17: 0.671 | K17: =H17*1.1 -> 0.7381
A18: 11 | B18: perfil aluminum | C18: 10cm I-shaped light strip (including lampshade) Thickness around 0.6 | F18: 3 | G18: meter | H18: 1.001 | K18: =H18*1.1 -> 1.1011
A19: 12 | B19: perfil aluminum | C19: 10 centimeter pointed yang angle Thickness around 0.5 | F19: 3 | G19: meter | H19: 0.671 | K19: =H19*1.1 -> 0.7381

Sheet Mobiliti
J2: SELECCIONAR SI LA COTIZACIÓN ESTARÁ EN MXN O USD
A3: Estrategia Descuentos vs GP | AA3: PRECIO CLIENTE O INTERMEDIARIO CUANDO APLIQUE | AH3: BUSCAR QUE SIEMPRE ESTE "OK"
A4: Precio TOTAL de Venta | E4: =AC573 -> 0 | J4: DÓLARES | K4: TRUE | U4: PRIMER PRECIO CARÁTULA
A5: Descuento: | Y5: OJO: BUSCAR EL NO DAR EL MÁXIMO DESCUENTO DE INICIO PARA TENER PODER DE NEGOCIACIÓN
A6: Subtotal: | E6: =E4*E5 -> 0 | J6: #VALUE! | K6: {=_FV(J6,"High")} -> 17.375
A8: GP COMERCIAL DE ESTA SECCIÓN | E8: =(AC573-M573)/AC573 -> #DIV/0! | J8: Lugar de entrega: | K8: #VALUE! | P8: {=IFERROR(_xlfn.XLOOKUP(K8,Fletes!C5:C17,Fletes!D5:F17),"No encontrado")} -> 37000 | Q8: 0 | R8: 0
P9: =P8/H573 -> #DIV/0!
A10: Instrucciones: Llenar SOLAMENTE las celdas en AMARILLO que apliquen.
A11: Intermediario | B11: NA | C11: Tipo de Moneda a Cotizar | D11: Código de Producto | E11: Producto | F11: Proveedor | G11: Código de Proveedor | H11: Cantidad | I11: CÁLCULO COSTO | W11: PRECIO DE VENTA | AT11: =IF(F15="Requiez",W15<=$AM$577,IF(F15="Labenze",W15<=$AM$578,IF(F15="Infinity",W15<=$AL$579,IF(F15="Offiho",W15<=$AL$580,IF(F15="MetalWork",W15<=$AL$581,IF(F15="Jome",W15<=$AL$582,IF(F15="Sunon Inc",W15<=$AL$583,IF(F15="Vandesk",W15<=$AL$584,IF(F15="Conceptos",W15<=$AL$585,IF(F15="Tarkett",W15<=$AL$586,IF(F15="Tarkett Stock",W15<=$AL$587,IF(F15="Tarkett Europa",W15<=$AL$588,IF(F15="Tarkett - Santeco /Nva.Ave",W15<=$AL$589,IF(F15="Lumbro",W15<=$AL$590,IF(F15="Cristales",W15<=$AL$591,IF(F15="Sunon Mty",W15<=$AL$592,IF(F15="Leds",W15<=$AL$593,IF(F15="Herrajes",W15<=$AL$594,IF(F15="Acabados",W15<=$AL$595,IF(F15="Andreu World",W15<=$AL$596,IF(F15="Lauco",W15<=$AL$597,IF(F15="Mamparas",W15<=$AL$598)))))))))))))))))))))) -> FALSE
I12: Descuento Proveedor | J12: Costo Unitario | K12: M3 | L12: M3 TOTALES | M12: Costo Unitario Real | N12: Costo Total | O12: % Margen | P12: Región | Q12: Flete | R12: Flete | S12: Instalación | T12: Instalación | U12: Flete + Instalación | V12: Flete + Instalación | W12: Precio Unitario de Lista (Carátula) | X12: Precio Lista | Y12: Descuento Máximo | Z12: Descuento Carátula | AA12: Precio Descontado | AB12: Precio Final c/ Descuento | AC12: Precio Total Comercial | AD12: Descuento Carátula Cliente Final | AE12: Precio Cliente con Ajuste | AF12: Precio Total Proyecto | AG12: GP COMERCIAL | AU12: NOTA: ESTE ES EL SUBTOTAL ANTES DE FLETE, INSTALACIÓN E IVA
A13: TRUE | C13: Dólares | D13: Sección 1 - NOMBRE
A14: =$A$13 -> TRUE | B14: =A14 -> TRUE | C14: =C13 -> Dólares | G14: =IFERROR(VLOOKUP(F14,Tabla_Proveedores_1,2,0)," ") | H14: 0 | I14: =IFERROR(VLOOKUP(G14,Proveedores!B:C,2,0)," ") | J14: 0 | K14: 0 | L14: =K14*H14 -> 0 | M14: =IF(F14="Offiho", J14*0.55, IF(AND(F14<>"Sunon Inc",F14<>"Alma - Exterior",F14<>"Yabo - Hotelería",F14<>"OSJ - Medical",F14<>"Seezo - Home",F14<>"A&D -Home",F14<>"Encore Alfombras Hoteleria Asia",F14<>"Zhong Xian - Leds",F14<>"Tarkett Europa",F14<>"2tec2",F14<>"Balsan Europa",F14<>"Armstrong Pisos USA",F14<>"Tarkett USA",F14<>"Tarkett Brasil"),J14,IFERROR(IF(K573<=$AO$578,J14*2.14,IF(K573<=$AN$579,J14*1.8,IF(K573>$AN$580,J14*1.5))),J14))*1.1) -> 0 | N14: =M14*H14 -> 0 | O14: =IFERROR(VLOOKUP(G14,Proveedores!B:D,3,0)," ") | Q14: =VLOOKUP(E14,Tabla_Fletes,3,FALSE) -> #N/A | R14: =IF(P14="Centro",Q14,IF(P14="Norte",Q14*1.6,IF(P14="Occidente",Q14*1.2,IF(P14="Sur",Q14*2)))) -> FALSE | S14: =VLOOKUP(E14,Tabla_Instalacion,2,FALSE) -> #N/A | T14: =IF(P14="Centro",S14,IF(P14="Norte",S14*1.1,IF(P14="Occidente",S14*1.1,IF(P14="Sur",S14*1.1)))) -> FALSE | U14: =IF(F14="Offiho",0,R14+T14) -> 0 | V14: =IF(K14=0,U14/$H$573,U14*(K14/L14))*H14 -> #DIV/0! | W14: =IF(F14="Offiho",J14,IF(_xlfn.XLOOKUP(F14,Proveedores!A$2:A$50,Proveedores!E$2:E$50,"")="Nacional",(J14/0.5)+(V14*H14),((J14/0.3/0.5)+(V14*H14)))) -> #DIV/0! | X14: =(W14*H14) -> #DIV/0! | Y14: =IF(F14="Sunon Inc",$AJ$577,IF(F14="Alma - Exterior",$AJ$578,IF(F14="Yabo - Hotelería",$AJ$579,IF(F14="OSJ - Medical",$AJ$580,IF(F14="Seezo - Home",$AJ$581,IF(F14="A&D - Home",$AJ$582,IF(F14="Encore Alfombras Hoteleria Asia",$AJ$583,IF(F14="Zhong Xian - Leds",$AJ$584,IF(F14="Tarkett Europa",$AJ$585,IF(F14="2tec2",$AJ$586,IF(F14="Balsan Europa",$AJ$587,IF(F14="Armstrong Pisos USA",$AJ$588,IF(F14="Tarkett USA",$AJ$589,IF(F14="Tarkett Brasil",$AJ$590,IF(F14="Tarkett MX",$AJ$591,IF(F14="Jome",$AJ$592,IF(F14="Offiho",$AJ$593,IF(F14="Lumbro",$AJ$594,IF(F14="Sunon Mty",$AJ$595,IF(F14="Conceptos Sofas",$AJ$596,IF(F14="Lauco Sofas",$AJ$597,IF(F14="CR Global - Mesas Ajustables",$AJ$598,IF(F14="Vandesk",$AJ$599,IF(F14="Mamparas Tela",$AJ$600,IF(F14="Mampara Cristales",$AJ$601,IF(F14="Herrajes",$AJ$602,IF(F14="MetalWork",$AJ$603,IF(F14="Requiez",$AJ$604,IF(F14="Labenze",$AJ$605,IF(F14="Infinity",$AJ$606,IF(F14="Proveedor Externo",$AJ$607))))))))))))))))))))))))))))))) -> FALSE | Z14: 0.5 | AA14: =W14*Z14 -> #DIV/0! | AB14: =IF(Z14>Y14,"ERROR",(W14-AA14)) -> #DIV/0! | AC14: =AB14*H14 -> #DIV/0! | AD14: =IF(A15=TRUE,MAX(0,1-(AE14/W14)),"NA") -> #DIV/0! | AE14: =IF(A13=FALSE,"NO APLICA",AB14*1.2) -> #DIV/0! | AF14: =AE14*H14 -> #DIV/0! | AG14: =(AC14-N14)/AC14 -> #DIV/0! | AH14: =IF(AG14<30%,"ERROR","OK") -> #DIV/0! | AR14: TABLA DE ESQUEMA COMISION INTERMEDIARIO
A15: =$A$13 -> TRUE | B15: =A15 -> TRUE | C15: =$C$13 -> Dólares | G15: =IFERROR(VLOOKUP(F15,Tabla_Proveedores_1,2,0)," ") | H15: 0 | I15: =IFERROR(VLOOKUP(G15,Proveedores!B:C,2,0)," ") | J15: 0 | K15: 0 | L15: =K15*H15 -> 0 | M15: =IF(F15="Offiho", J15*0.55, IF(AND(F15<>"Sunon Inc",F15<>"Alma - Exterior",F15<>"Yabo - Hotelería",F15<>"OSJ - Medical",F15<>"Seezo - Home",F15<>"A&D -Home",F15<>"Encore Alfombras Hoteleria Asia",F15<>"Zhong Xian - Leds",F15<>"Tarkett Europa",F15<>"2tec2",F15<>"Balsan Europa",F15<>"Armstrong Pisos USA",F15<>"Tarkett USA",F15<>"Tarkett Brasil"),J15,IFERROR(IF(K574<=$AO$578,J15*2.14,IF(K574<=$AN$579,J15*1.8,IF(K574>$AN$580,J15*1.5))),J15))*1.1) -> 0 | N15: =M15*H15 -> 0 | O15: =IFERROR(VLOOKUP(G15,Proveedores!B:D,3,0)," ") | Q15: =VLOOKUP(E15,Tabla_Fletes,3,FALSE) -> #N/A | R15: =IF(P15="Centro",Q15,IF(P15="Norte",Q15*1.6,IF(P15="Occidente",Q15*1.2,IF(P15="Sur",Q15*2)))) -> FALSE | S15: =VLOOKUP(E15,Tabla_Instalacion,2,FALSE) -> #N/A | T15: =IF(P15="Centro",S15,IF(P15="Norte",S15*1.1,IF(P15="Occidente",S15*1.1,IF(P15="Sur",S15*1.1)))) -> FALSE | U15: =IF(F15="Offiho",0,R15+T15) -> 0 | V15: =IF(K15=0,U15/$H$573,U15*(K15/L15))*H15 -> #DIV/0! | W15: =IF(F15="Offiho",J15,IF(_xlfn.XLOOKUP(F15,Proveedores!A$2:A$50,Proveedores!E$2:E$50,"")="Nacional",(J15/0.5)+(V15*H15),((J15/0.3/0.5)+(V15*H15)))) -> #DIV/0! | X15: =(W15*H15) -> #DIV/0! | Y15: =IF(F15="Sunon Inc",$AJ$577,IF(F15="Alma - Exterior",$AJ$578,IF(F15="Yabo - Hotelería",$AJ$579,IF(F15="OSJ - Medical",$AJ$580,IF(F15="Seezo - Home",$AJ$581,IF(F15="A&D - Home",$AJ$582,IF(F15="Encore Alfombras Hoteleria Asia",$AJ$583,IF(F15="Zhong Xian - Leds",$AJ$584,IF(F15="Tarkett Europa",$AJ$585,IF(F15="2tec2",$AJ$586,IF(F15="Balsan Europa",$AJ$587,IF(F15="Armstrong Pisos USA",$AJ$588,IF(F15="Tarkett USA",$AJ$589,IF(F15="Tarkett Brasil",$AJ$590,IF(F15="Tarkett MX",$AJ$591,IF(F15="Jome",$AJ$592,IF(F15="Offiho",$AJ$593,IF(F15="Lumbro",$AJ$594,IF(F15="Sunon Mty",$AJ$595,IF(F15="Conceptos Sofas",$AJ$596,IF(F15="Lauco Sofas",$AJ$597,IF(F15="CR Global - Mesas Ajustables",$AJ$598,IF(F15="Vandesk",$AJ$599,IF(F15="Mamparas Tela",$AJ$600,IF(F15="Mampara Cristales",$AJ$601,IF(F15="Herrajes",$AJ$602,IF(F15="MetalWork",$AJ$603,IF(F15="Requiez",$AJ$604,IF(F15="Labenze",$AJ$605,IF(F15="Infinity",$AJ$606,IF(F15="Proveedor Externo",$AJ$607))))))))))))))))))))))))))))))) -> FALSE | Z15: 0.5 | AA15: =W15*Z15 -> #DIV/0! | AB15: =IF(Z15>Y15,"ERROR",(W15-AA15)) -> #DIV/0! | AC15: =AB15*H15 -> #DIV/0! | AD15: =IF(A16=TRUE,MAX(0,1-(AE15/W15)),"NA") -> #DIV/0! | AE15: =IF(A14=FALSE,"NO APLICA",AB15*1.2) -> #DIV/0! | AF15: =AE15*H15 -> #DIV/0! | AG15: =(AC15-N15)/AC15 -> #DIV/0! | AH15: =IF(AG15<30%,"ERROR","OK") -> #DIV/0! | AR15: Precio de Venta Base | AS15: =AC573 -> 0
A16: =$A$13 -> TRUE | B16: =A16 -> TRUE | C16: =$C$13 -> Dólares | G16: =IFERROR(VLOOKUP(F16,Tabla_Proveedores_1,2,0)," ") | H16: 0 | I16: =IFERROR(VLOOKUP(G16,Proveedores!B:C,2,0)," ") | J16: 0 | K16: 0 | L16: =K16*H16 -> 0 | M16: =IF(F16="Offiho", J16*0.55, IF(AND(F16<>"Sunon Inc",F16<>"Alma - Exterior",F16<>"Yabo - Hotelería",F16<>"OSJ - Medical",F16<>"Seezo - Home",F16<>"A&D -Home",F16<>"Encore Alfombras Hoteleria Asia",F16<>"Zhong Xian - Leds",F16<>"Tarkett Europa",F16<>"2tec2",F16<>"Balsan Europa",F16<>"Armstrong Pisos USA",F16<>"Tarkett USA",F16<>"Tarkett Brasil"),J16,IFERROR(IF(K575<=$AO$578,J16*2.14,IF(K575<=$AN$579,J16*1.8,IF(K575>$AN$580,J16*1.5))),J16))*1.1) -> 0 | N16: =M16*H16 -> 0 | O16: =IFERROR(VLOOKUP(G16,Proveedores!B:D,3,0)," ") | Q16: =VLOOKUP(E16,Tabla_Fletes,3,FALSE) -> #N/A | R16: =IF(P16="Centro",Q16,IF(P16="Norte",Q16*1.6,IF(P16="Occidente",Q16*1.2,IF(P16="Sur",Q16*2)))) -> FALSE | S16: =VLOOKUP(E16,Tabla_Instalacion,2,FALSE) -> #N/A | T16: =IF(P16="Centro",S16,IF(P16="Norte",S16*1.1,IF(P16="Occidente",S16*1.1,IF(P16="Sur",S16*1.1)))) -> FALSE | U16: =IF(F16="Offiho",0,R16+T16) -> 0 | V16: =IF(K16=0,U16/$H$573,U16*(K16/L16))*H16 -> #DIV/0! | W16: =IF(F16="Offiho",J16,IF(_xlfn.XLOOKUP(F16,Proveedores!A$2:A$50,Proveedores!E$2:E$50,"")="Nacional",(J16/0.5)+(V16*H16),((J16/0.3/0.5)+(V16*H16)))) -> #DIV/0! | X16: =(W16*H16) -> #DIV/0! | Y16: =IF(F16="Sunon Inc",$AJ$577,IF(F16="Alma - Exterior",$AJ$578,IF(F16="Yabo - Hotelería",$AJ$579,IF(F16="OSJ - Medical",$AJ$580,IF(F16="Seezo - Home",$AJ$581,IF(F16="A&D - Home",$AJ$582,IF(F16="Encore Alfombras Hoteleria Asia",$AJ$583,IF(F16="Zhong Xian - Leds",$AJ$584,IF(F16="Tarkett Europa",$AJ$585,IF(F16="2tec2",$AJ$586,IF(F16="Balsan Europa",$AJ$587,IF(F16="Armstrong Pisos USA",$AJ$588,IF(F16="Tarkett USA",$AJ$589,IF(F16="Tarkett Brasil",$AJ$590,IF(F16="Tarkett MX",$AJ$591,IF(F16="Jome",$AJ$592,IF(F16="Offiho",$AJ$593,IF(F16="Lumbro",$AJ$594,IF(F16="Sunon Mty",$AJ$595,IF(F16="Conceptos Sofas",$AJ$596,IF(F16="Lauco Sofas",$AJ$597,IF(F16="CR Global - Mesas Ajustables",$AJ$598,IF(F16="Vandesk",$AJ$599,IF(F16="Mamparas Tela",$AJ$600,IF(F16="Mampara Cristales",$AJ$601,IF(F16="Herrajes",$AJ$602,IF(F16="MetalWork",$AJ$603,IF(F16="Requiez",$AJ$604,IF(F16="Labenze",$AJ$605,IF(F16="Infinity",$AJ$606,IF(F16="Proveedor Externo",$AJ$607))))))))))))))))))))))))))))))) -> FALSE | Z16: 0.5 | AA16: =W16*Z16 -> #DIV/0! | AB16: =IF(Z16>Y16,"ERROR",(W16-AA16)) -> #DIV/0! | AC16: =AB16*H16 -> #DIV/0! | AD16: =IF(A17=TRUE,MAX(0,1-(AE16/W16)),"NA") -> #DIV/0! | AE16: =IF(A15=FALSE,"NO APLICA",AB16*1.2) -> #DIV/0! | AF16: =AE16*H16 -> #DIV/0! | AG16: =(AC16-N16)/AC16 -> #DIV/0! | AH16: =IF(AG16<30%,"ERROR","OK") -> #DIV/0! | AR16: Precio de Venta Final | AS16: =AF573 -> 0
A17: =$A$13 -> TRUE | B17: =A17 -> TRUE | C17: =$C$13 -> Dólares | G17: =IFERROR(VLOOKUP(F17,Tabla_Proveedores_1,2,0)," ") | H17: 0 | I17: =IFERROR(VLOOKUP(G17,Proveedores!B:C,2,0)," ") | J17: 0 | K17: 0 | L17: =K17*H17 -> 0 | M17: =IF(F17="Offiho", J17*0.55, IF(AND(F17<>"Sunon Inc",F17<>"Alma - Exterior",F17<>"Yabo - Hotelería",F17<>"OSJ - Medical",F17<>"Seezo - Home",F17<>"A&D -Home",F17<>"Encore Alfombras Hoteleria Asia",F17<>"Zhong Xian - Leds",F17<>"Tarkett Europa",F17<>"2tec2",F17<>"Balsan Europa",F17<>"Armstrong Pisos USA",F17<>"Tarkett USA",F17<>"Tarkett Brasil"),J17,IFERROR(IF(K576<=$AO$578,J17*2.14,IF(K576<=$AN$579,J17*1.8,IF(K576>$AN$580,J17*1.5))),J17))*1.1) -> 0 | N17: =M17*H17 -> 0 | O17: =IFERROR(VLOOKUP(G17,Proveedores!B:D,3,0)," ") | Q17: =VLOOKUP(E17,Tabla_Fletes,3,FALSE) -> #N/A | R17: =IF(P17="Centro",Q17,IF(P17="Norte",Q17*1.6,IF(P17="Occidente",Q17*1.2,IF(P17="Sur",Q17*2)))) -> FALSE | S17: =VLOOKUP(E17,Tabla_Instalacion,2,FALSE) -> #N/A | T17: =IF(P17="Centro",S17,IF(P17="Norte",S17*1.1,IF(P17="Occidente",S17*1.1,IF(P17="Sur",S17*1.1)))) -> FALSE | U17: =IF(F17="Offiho",0,R17+T17) -> 0 | V17: =IF(K17=0,U17/$H$573,U17*(K17/L17))*H17 -> #DIV/0! | W17: =IF(F17="Offiho",J17,IF(_xlfn.XLOOKUP(F17,Proveedores!A$2:A$50,Proveedores!E$2:E$50,"")="Nacional",(J17/0.5)+(V17*H17),((J17/0.3/0.5)+(V17*H17)))) -> #DIV/0! | X17: =(W17*H17) -> #DIV/0! | Y17: =IF(F17="Sunon Inc",$AJ$577,IF(F17="Alma - Exterior",$AJ$578,IF(F17="Yabo - Hotelería",$AJ$579,IF(F17="OSJ - Medical",$AJ$580,IF(F17="Seezo - Home",$AJ$581,IF(F17="A&D - Home",$AJ$582,IF(F17="Encore Alfombras Hoteleria Asia",$AJ$583,IF(F17="Zhong Xian - Leds",$AJ$584,IF(F17="Tarkett Europa",$AJ$585,IF(F17="2tec2",$AJ$586,IF(F17="Balsan Europa",$AJ$587,IF(F17="Armstrong Pisos USA",$AJ$588,IF(F17="Tarkett USA",$AJ$589,IF(F17="Tarkett Brasil",$AJ$590,IF(F17="Tarkett MX",$AJ$591,IF(F17="Jome",$AJ$592,IF(F17="Offiho",$AJ$593,IF(F17="Lumbro",$AJ$594,IF(F17="Sunon Mty",$AJ$595,IF(F17="Conceptos Sofas",$AJ$596,IF(F17="Lauco Sofas",$AJ$597,IF(F17="CR Global - Mesas Ajustables",$AJ$598,IF(F17="Vandesk",$AJ$599,IF(F17="Mamparas Tela",$AJ$600,IF(F17="Mampara Cristales",$AJ$601,IF(F17="Herrajes",$AJ$602,IF(F17="MetalWork",$AJ$603,IF(F17="Requiez",$AJ$604,IF(F17="Labenze",$AJ$605,IF(F17="Infinity",$AJ$606,IF(F17="Proveedor Externo",$AJ$607))))))))))))))))))))))))))))))) -> FALSE | Z17: 0.5 | AA17: =W17*Z17 -> #DIV/0! | AB17: =IF(Z17>Y17,"ERROR",(W17-AA17)) -> #DIV/0! | AC17: =AB17*H17 -> #DIV/0! | AD17: =IF(A18=TRUE,MAX(0,1-(AE17/W17)),"NA") -> #DIV/0! | AE17: =IF(A16=FALSE,"NO APLICA",AB17*1.2) -> #DIV/0! | AF17: =AE17*H17 -> #DIV/0! | AG17: =(AC17-N17)/AC17 -> #DIV/0! | AH17: =IF(AG17<30%,"ERROR","OK") -> #DIV/0! | AR17: Monto Comisión | AS17: =AS16-AS15 -> 0
A18: =$A$13 -> TRUE | B18: =A18 -> TRUE | C18: =$C$13 -> Dólares | G18: =IFERROR(VLOOKUP(F18,Tabla_Proveedores_1,2,0)," ") | H18: 0 | I18: =IFERROR(VLOOKUP(G18,Proveedores!B:C,2,0)," ") | J18: 0 | L18: =K18*H18 -> 0 | M18: =IF(F18="Offiho", J18*0.55, IF(AND(F18<>"Sunon Inc",F18<>"Alma - Exterior",F18<>"Yabo - Hotelería",F18<>"OSJ - Medical",F18<>"Seezo - Home",F18<>"A&D -Home",F18<>"Encore Alfombras Hoteleria Asia",F18<>"Zhong Xian - Leds",F18<>"Tarkett Europa",F18<>"2tec2",F18<>"Balsan Europa",F18<>"Armstrong Pisos USA",F18<>"Tarkett USA",F18<>"Tarkett Brasil"),J18,IFERROR(IF(K577<=$AO$578,J18*2.14,IF(K577<=$AN$579,J18*1.8,IF(K577>$AN$580,J18*1.5))),J18))*1.1) -> 0 | N18: =M18*H18 -> 0 | O18: =IFERROR(VLOOKUP(G18,Proveedores!B:D,3,0)," ") | Q18: =VLOOKUP(E18,Tabla_Fletes,3,FALSE) -> #N/A | R18: =IF(P18="Centro",Q18,IF(P18="Norte",Q18*1.6,IF(P18="Occidente",Q18*1.2,IF(P18="Sur",Q18*2)))) -> FALSE | S18: =VLOOKUP(E18,Tabla_Instalacion,2,FALSE) -> #N/A | T18: =IF(P18="Centro",S18,IF(P18="Norte",S18*1.1,IF(P18="Occidente",S18*1.1,IF(P18="Sur",S18*1.1)))) -> FALSE | U18: =IF(F18="Offiho",0,R18+T18) -> 0 | V18: =IF(K18=0,U18/$H$573,U18*(K18/L18))*H18 -> #DIV/0! | W18: =IF(F18="Offiho",J18,IF(_xlfn.XLOOKUP(F18,Proveedores!A$2:A$50,Proveedores!E$2:E$50,"")="Nacional",(J18/0.5)+(V18*H18),((J18/0.3/0.5)+(V18*H18)))) -> #DIV/0! | X18: =(W18*H18) -> #DIV/0! | Y18: =IF(F18="Sunon Inc",$AJ$577,IF(F18="Alma - Exterior",$AJ$578,IF(F18="Yabo - Hotelería",$AJ$579,IF(F18="OSJ - Medical",$AJ$580,IF(F18="Seezo - Home",$AJ$581,IF(F18="A&D - Home",$AJ$582,IF(F18="Encore Alfombras Hoteleria Asia",$AJ$583,IF(F18="Zhong Xian - Leds",$AJ$584,IF(F18="Tarkett Europa",$AJ$585,IF(F18="2tec2",$AJ$586,IF(F18="Balsan Europa",$AJ$587,IF(F18="Armstrong Pisos USA",$AJ$588,IF(F18="Tarkett USA",$AJ$589,IF(F18="Tarkett Brasil",$AJ$590,IF(F18="Tarkett MX",$AJ$591,IF(F18="Jome",$AJ$592,IF(F18="Offiho",$AJ$593,IF(F18="Lumbro",$AJ$594,IF(F18="Sunon Mty",$AJ$595,IF(F18="Conceptos Sofas",$AJ$596,IF(F18="Lauco Sofas",$AJ$597,IF(F18="CR Global - Mesas Ajustables",$AJ$598,IF(F18="Vandesk",$AJ$599,IF(F18="Mamparas Tela",$AJ$600,IF(F18="Mampara Cristales",$AJ$601,IF(F18="Herrajes",$AJ$602,IF(F18="MetalWork",$AJ$603,IF(F18="Requiez",$AJ$604,IF(F18="Labenze",$AJ$605,IF(F18="Infinity",$AJ$606,IF(F18="Proveedor Externo",$AJ$607))))))))))))))))))))))))))))))) -> FALSE | Z18: 0 | AA18: =W18*Z18 -> #DIV/0! | AB18: =IF(Z18>Y18,"ERROR",(W18-AA18)) -> #DIV/0! | AC18: =AB18*H18 -> #DIV/0! | AD18: =IF(A19=TRUE,MAX(0,1-(AE18/W18)),"NA") -> #DIV/0! | AE18: =IF(A17=FALSE,"NO APLICA",AB18*1.2) -> #DIV/0! | AF18: =AE18*H18 -> #DIV/0! | AG18: =(AC18-N18)/AC18 -> #DIV/0! | AH18: =IF(AG18<30%,"ERROR","OK") -> #DIV/0! | AR18: % Resultante | AS18: =(AS16/AS15)-1 -> #DIV/0! | AT18: 20% de comisión
A19: =$A$13 -> TRUE | B19: =A19 -> TRUE | C19: =$C$13 -> Dólares | G19: =IFERROR(VLOOKUP(F19,Tabla_Proveedores_1,2,0)," ") | H19: 0 | I19: =IFERROR(VLOOKUP(G19,Proveedores!B:C,2,0)," ") | J19: 0 | L19: =K19*H19 -> 0 | M19: =IF(F19="Offiho", J19*0.55, IF(AND(F19<>"Sunon Inc",F19<>"Alma - Exterior",F19<>"Yabo - Hotelería",F19<>"OSJ - Medical",F19<>"Seezo - Home",F19<>"A&D -Home",F19<>"Encore Alfombras Hoteleria Asia",F19<>"Zhong Xian - Leds",F19<>"Tarkett Europa",F19<>"2tec2",F19<>"Balsan Europa",F19<>"Armstrong Pisos USA",F19<>"Tarkett USA",F19<>"Tarkett Brasil"),J19,IFERROR(IF(K578<=$AO$578,J19*2.14,IF(K578<=$AN$579,J19*1.8,IF(K578>$AN$580,J19*1.5))),J19))*1.1) -> 0 | N19: =M19*H19 -> 0 | O19: =IFERROR(VLOOKUP(G19,Proveedores!B:D,3,0)," ") | Q19: =VLOOKUP(E19,Tabla_Fletes,3,FALSE) -> #N/A | R19: =IF(P19="Centro",Q19,IF(P19="Norte",Q19*1.6,IF(P19="Occidente",Q19*1.2,IF(P19="Sur",Q19*2)))) -> FALSE | S19: =VLOOKUP(E19,Tabla_Instalacion,2,FALSE) -> #N/A | T19: =IF(P19="Centro",S19,IF(P19="Norte",S19*1.1,IF(P19="Occidente",S19*1.1,IF(P19="Sur",S19*1.1)))) -> FALSE | U19: =IF(F19="Offiho",0,R19+T19) -> 0 | V19: =IF(K19=0,U19/$H$573,U19*(K19/L19))*H19 -> #DIV/0! | W19: =IF(F19="Offiho",J19,IF(_xlfn.XLOOKUP(F19,Proveedores!A$2:A$50,Proveedores!E$2:E$50,"")="Nacional",(J19/0.5)+(V19*H19),((J19/0.3/0.5)+(V19*H19)))) -> #DIV/0! | X19: =(W19*H19) -> #DIV/0! | Y19: =IF(F19="Sunon Inc",$AJ$577,IF(F19="Alma - Exterior",$AJ$578,IF(F19="Yabo - Hotelería",$AJ$579,IF(F19="OSJ - Medical",$AJ$580,IF(F19="Seezo - Home",$AJ$581,IF(F19="A&D - Home",$AJ$582,IF(F19="Encore Alfombras Hoteleria Asia",$AJ$583,IF(F19="Zhong Xian - Leds",$AJ$584,IF(F19="Tarkett Europa",$AJ$585,IF(F19="2tec2",$AJ$586,IF(F19="Balsan Europa",$AJ$587,IF(F19="Armstrong Pisos USA",$AJ$588,IF(F19="Tarkett USA",$AJ$589,IF(F19="Tarkett Brasil",$AJ$590,IF(F19="Tarkett MX",$AJ$591,IF(F19="Jome",$AJ$592,IF(F19="Offiho",$AJ$593,IF(F19="Lumbro",$AJ$594,IF(F19="Sunon Mty",$AJ$595,IF(F19="Conceptos Sofas",$AJ$596,IF(F19="Lauco Sofas",$AJ$597,IF(F19="CR Global - Mesas Ajustables",$AJ$598,IF(F19="Vandesk",$AJ$599,IF(F19="Mamparas Tela",$AJ$600,IF(F19="Mampara Cristales",$AJ$601,IF(F19="Herrajes",$AJ$602,IF(F19="MetalWork",$AJ$603,IF(F19="Requiez",$AJ$604,IF(F19="Labenze",$AJ$605,IF(F19="Infinity",$AJ$606,IF(F19="Proveedor Externo",$AJ$607))))))))))))))))))))))))))))))) -> FALSE | Z19: 0 | AA19: =W19*Z19 -> #DIV/0! | AB19: =IF(Z19>Y19,"ERROR",(W19-AA19)) -> #DIV/0! | AC19: =AB19*H19 -> #DIV/0! | AD19: =IF(A20=TRUE,MAX(0,1-(AE19/W19)),"NA") -> #DIV/0! | AE19: =IF(A18=FALSE,"NO APLICA",AB19*1.2) -> #DIV/0! | AF19: =AE19*H19 -> #DIV/0! | AG19: =(AC19-N19)/AC19 -> #DIV/0! | AH19: =IF(AG19<30%,"ERROR","OK") -> #DIV/0!
A20: =$A$13 -> TRUE | B20: =A20 -> TRUE | C20: =$C$13 -> Dólares | G20: =IFERROR(VLOOKUP(F20,Tabla_Proveedores_1,2,0)," ") | H20: 0 | I20: =IFERROR(VLOOKUP(G20,Proveedores!B:C,2,0)," ") | J20: 0 | L20: =K20*H20 -> 0 | M20: =IF(F20="Offiho", J20*0.55, IF(AND(F20<>"Sunon Inc",F20<>"Alma - Exterior",F20<>"Yabo - Hotelería",F20<>"OSJ - Medical",F20<>"Seezo - Home",F20<>"A&D -Home",F20<>"Encore Alfombras Hoteleria Asia",F20<>"Zhong Xian - Leds",F20<>"Tarkett Europa",F20<>"2tec2",F20<>"Balsan Europa",F20<>"Armstrong Pisos USA",F20<>"Tarkett USA",F20<>"Tarkett Brasil"),J20,IFERROR(IF(J579<=$AO$578,J20*2.14,IF(J579<=$AN$579,J20*1.8,IF(J579>$AN$580,J20*1.5))),J20))*1.1) -> 0 | N20: =M20*H20 -> 0 | O20: =IFERROR(VLOOKUP(G20,Proveedores!B:D,3,0)," ") | Q20: =VLOOKUP(E20,Tabla_Fletes,3,FALSE) -> #N/A | R20: =IF(P20="Centro",Q20,IF(P20="Norte",Q20*1.6,IF(P20="Occidente",Q20*1.2,IF(P20="Sur",Q20*2)))) -> FALSE | S20: =VLOOKUP(E20,Tabla_Instalacion,2,FALSE) -> #N/A | T20: =IF(P20="Centro",S20,IF(P20="Norte",S20*1.1,IF(P20="Occidente",S20*1.1,IF(P20="Sur",S20*1.1)))) -> FALSE | U20: =IF(F20="Offiho",0,R20+T20) -> 0 | V20: =IF(K20=0,U20/$H$573,U20*(K20/L20))*H20 -> #DIV/0! | W20: =IF(F20="Offiho",J20,IF(_xlfn.XLOOKUP(F20,Proveedores!A$2:A$50,Proveedores!E$2:E$50,"")="Nacional",(J20/0.5)+(V20*H20),((J20/0.3/0.5)+(V20*H20)))) -> #DIV/0! | X20: =(W20*H20) -> #DIV/0! | Y20: =IF(F20="Sunon Inc",$AJ$577,IF(F20="Alma - Exterior",$AJ$578,IF(F20="Yabo - Hotelería",$AJ$579,IF(F20="OSJ - Medical",$AJ$580,IF(F20="Seezo - Home",$AJ$581,IF(F20="A&D - Home",$AJ$582,IF(F20="Encore Alfombras Hoteleria Asia",$AJ$583,IF(F20="Zhong Xian - Leds",$AJ$584,IF(F20="Tarkett Europa",$AJ$585,IF(F20="2tec2",$AJ$586,IF(F20="Balsan Europa",$AJ$587,IF(F20="Armstrong Pisos USA",$AJ$588,IF(F20="Tarkett USA",$AJ$589,IF(F20="Tarkett Brasil",$AJ$590,IF(F20="Tarkett MX",$AJ$591,IF(F20="Jome",$AJ$592,IF(F20="Offiho",$AJ$593,IF(F20="Lumbro",$AJ$594,IF(F20="Sunon Mty",$AJ$595,IF(F20="Conceptos Sofas",$AJ$596,IF(F20="Lauco Sofas",$AJ$597,IF(F20="CR Global - Mesas Ajustables",$AJ$598,IF(F20="Vandesk",$AJ$599,IF(F20="Mamparas Tela",$AJ$600,IF(F20="Mampara Cristales",$AJ$601,IF(F20="Herrajes",$AJ$602,IF(F20="MetalWork",$AJ$603,IF(F20="Requiez",$AJ$604,IF(F20="Labenze",$AJ$605,IF(F20="Infinity",$AJ$606,IF(F20="Proveedor Externo",$AJ$607))))))))))))))))))))))))))))))) -> FALSE | Z20: 0 | AA20: =W20*Z20 -> #DIV/0! | AB20: =IF(Z20>Y20,"ERROR",(W20-AA20)) -> #DIV/0! | AC20: =AB20*H20 -> #DIV/0! | AD20: =IF(A21=TRUE,MAX(0,1-(AE20/W20)),"NA") -> #DIV/0! | AE20: =IF(A19=FALSE,"NO APLICA",AB20*1.2) -> #DIV/0! | AF20: =AE20*H20 -> #DIV/0! | AG20: =(AC20-N20)/AC20 -> #DIV/0! | AH20: =IF(AG20<30%,"ERROR","OK") -> #DIV/0!
A21: =$A$13 -> TRUE | B21: =A21 -> TRUE | C21: =$C$13 -> Dólares | G21: =IFERROR(VLOOKUP(F21,Tabla_Proveedores_1,2,0)," ") | H21: 0 | I21: =IFERROR(VLOOKUP(G21,Proveedores!B:C,2,0)," ") | J21: 0 | L21: =K21*H21 -> 0 | M21: =IF(F21="Offiho", J21*0.55, IF(AND(F21<>"Sunon Inc",F21<>"Alma - Exterior",F21<>"Yabo - Hotelería",F21<>"OSJ - Medical",F21<>"Seezo - Home",F21<>"A&D -Home",F21<>"Encore Alfombras Hoteleria Asia",F21<>"Zhong Xian - Leds",F21<>"Tarkett Europa",F21<>"2tec2",F21<>"Balsan Europa",F21<>"Armstrong Pisos USA",F21<>"Tarkett USA",F21<>"Tarkett Brasil"),J21,IFERROR(IF(J580<=$AO$578,J21*2.14,IF(J580<=$AN$579,J21*1.8,IF(J580>$AN$580,J21*1.5))),J21))*1.1) -> 0 | N21: =M21*H21 -> 0 | O21: =IFERROR(VLOOKUP(G21,Proveedores!B:D,3,0)," ") | Q21: =VLOOKUP(E21,Tabla_Fletes,3,FALSE) -> #N/A | R21: =IF(P21="Centro",Q21,IF(P21="Norte",Q21*1.6,IF(P21="Occidente",Q21*1.2,IF(P21="Sur",Q21*2)))) -> FALSE | S21: =VLOOKUP(E21,Tabla_Instalacion,2,FALSE) -> #N/A | T21: =IF(P21="Centro",S21,IF(P21="Norte",S21*1.1,IF(P21="Occidente",S21*1.1,IF(P21="Sur",S21*1.1)))) -> FALSE | U21: =IF(F21="Offiho",0,R21+T21) -> 0 | V21: =IF(K21=0,U21/$H$573,U21*(K21/L21))*H21 -> #DIV/0! | W21: =IF(F21="Offiho",J21,IF(_xlfn.XLOOKUP(F21,Proveedores!A$2:A$50,Proveedores!E$2:E$50,"")="Nacional",(J21/0.5)+(V21*H21),((J21/0.3/0.5)+(V21*H21)))) -> #DIV/0! | X21: =(W21*H21) -> #DIV/0! | Y21: =IF(F21="Sunon Inc",$AJ$577,IF(F21="Alma - Exterior",$AJ$578,IF(F21="Yabo - Hotelería",$AJ$579,IF(F21="OSJ - Medical",$AJ$580,IF(F21="Seezo - Home",$AJ$581,IF(F21="A&D - Home",$AJ$582,IF(F21="Encore Alfombras Hoteleria Asia",$AJ$583,IF(F21="Zhong Xian - Leds",$AJ$584,IF(F21="Tarkett Europa",$AJ$585,IF(F21="2tec2",$AJ$586,IF(F21="Balsan Europa",$AJ$587,IF(F21="Armstrong Pisos USA",$AJ$588,IF(F21="Tarkett USA",$AJ$589,IF(F21="Tarkett Brasil",$AJ$590,IF(F21="Tarkett MX",$AJ$591,IF(F21="Jome",$AJ$592,IF(F21="Offiho",$AJ$593,IF(F21="Lumbro",$AJ$594,IF(F21="Sunon Mty",$AJ$595,IF(F21="Conceptos Sofas",$AJ$596,IF(F21="Lauco Sofas",$AJ$597,IF(F21="CR Global - Mesas Ajustables",$AJ$598,IF(F21="Vandesk",$AJ$599,IF(F21="Mamparas Tela",$AJ$600,IF(F21="Mampara Cristales",$AJ$601,IF(F21="Herrajes",$AJ$602,IF(F21="MetalWork",$AJ$603,IF(F21="Requiez",$AJ$604,IF(F21="Labenze",$AJ$605,IF(F21="Infinity",$AJ$606,IF(F21="Proveedor Externo",$AJ$607))))))))))))))))))))))))))))))) -> FALSE | Z21: 0 | AA21: =W21*Z21 -> #DIV/0! | AB21: =IF(Z21>Y21,"ERROR",(W21-AA21)) -> #DIV/0! | AC21: =AB21*H21 -> #DIV/0! | AD21: =IF(A22=TRUE,MAX(0,1-(AE21/W21)),"NA") -> #DIV/0! | AE21: =IF(A20=FALSE,"NO APLICA",AB21*1.2) -> #DIV/0! | AF21: =AE21*H21 -> #DIV/0! | AG21: =(AC21-N21)/AC21 -> #DIV/0! | AH21: =IF(AG21<30%,"ERROR","OK") -> #DIV/0!
A22: =$A$13 -> TRUE | B22: =A22 -> TRUE | C22: =$C$13 -> Dólares | G22: =IFERROR(VLOOKUP(F22,Tabla_Proveedores_1,2,0)," ") | H22: 0 | I22: =IFERROR(VLOOKUP(G22,Proveedores!B:C,2,0)," ") | J22: 0 | L22: =K22*H22 -> 0 | M22: =IF(F22="Offiho", J22*0.55, IF(AND(F22<>"Sunon Inc",F22<>"Alma - Exterior",F22<>"Yabo - Hotelería",F22<>"OSJ - Medical",F22<>"Seezo - Home",F22<>"A&D -Home",F22<>"Encore Alfombras Hoteleria Asia",F22<>"Zhong Xian - Leds",F22<>"Tarkett Europa",F22<>"2tec2",F22<>"Balsan Europa",F22<>"Armstrong Pisos USA",F22<>"Tarkett USA",F22<>"Tarkett Brasil"),J22,IFERROR(IF(J581<=$AO$578,J22*2.14,IF(J581<=$AN$579,J22*1.8,IF(J581>$AN$580,J22*1.5))),J22))*1.1) -> 0 | N22: =M22*H22 -> 0 | O22: =IFERROR(VLOOKUP(G22,Proveedores!B:D,3,0)," ") | Q22: =VLOOKUP(E22,Tabla_Fletes,3,FALSE) -> #N/A | R22: =IF(P22="Centro",Q22,IF(P22="Norte",Q22*1.6,IF(P22="Occidente",Q22*1.2,IF(P22="Sur",Q22*2)))) -> FALSE | S22: =VLOOKUP(E22,Tabla_Instalacion,2,FALSE) -> #N/A | T22: =IF(P22="Centro",S22,IF(P22="Norte",S22*1.1,IF(P22="Occidente",S22*1.1,IF(P22="Sur",S22*1.1)))) -> FALSE | U22: =IF(F22="Offiho",0,R22+T22) -> 0 | V22: =IF(K22=0,U22/$H$573,U22*(K22/L22))*H22 -> #DIV/0! | W22: =IF(F22="Offiho",J22,IF(_xlfn.XLOOKUP(F22,Proveedores!A$2:A$50,Proveedores!E$2:E$50,"")="Nacional",(J22/0.5)+(V22*H22),((J22/0.3/0.5)+(V22*H22)))) -> #DIV/0! | X22: =(W22*H22) -> #DIV/0! | Y22: =IF(F22="Sunon Inc",$AJ$577,IF(F22="Alma - Exterior",$AJ$578,IF(F22="Yabo - Hotelería",$AJ$579,IF(F22="OSJ - Medical",$AJ$580,IF(F22="Seezo - Home",$AJ$581,IF(F22="A&D - Home",$AJ$582,IF(F22="Encore Alfombras Hoteleria Asia",$AJ$583,IF(F22="Zhong Xian - Leds",$AJ$584,IF(F22="Tarkett Europa",$AJ$585,IF(F22="2tec2",$AJ$586,IF(F22="Balsan Europa",$AJ$587,IF(F22="Armstrong Pisos USA",$AJ$588,IF(F22="Tarkett USA",$AJ$589,IF(F22="Tarkett Brasil",$AJ$590,IF(F22="Tarkett MX",$AJ$591,IF(F22="Jome",$AJ$592,IF(F22="Offiho",$AJ$593,IF(F22="Lumbro",$AJ$594,IF(F22="Sunon Mty",$AJ$595,IF(F22="Conceptos Sofas",$AJ$596,IF(F22="Lauco Sofas",$AJ$597,IF(F22="CR Global - Mesas Ajustables",$AJ$598,IF(F22="Vandesk",$AJ$599,IF(F22="Mamparas Tela",$AJ$600,IF(F22="Mampara Cristales",$AJ$601,IF(F22="Herrajes",$AJ$602,IF(F22="MetalWork",$AJ$603,IF(F22="Requiez",$AJ$604,IF(F22="Labenze",$AJ$605,IF(F22="Infinity",$AJ$606,IF(F22="Proveedor Externo",$AJ$607))))))))))))))))))))))))))))))) -> FALSE | Z22: 0 | AA22: =W22*Z22 -> #DIV/0! | AB22: =IF(Z22>Y22,"ERROR",(W22-AA22)) -> #DIV/0! | AC22: =AB22*H22 -> #DIV/0! | AD22: =IF(A23=TRUE,MAX(0,1-(AE22/W22)),"NA") -> #DIV/0! | AE22: =IF(A21=FALSE,"NO APLICA",AB22*1.2) -> #DIV/0! | AF22: =AE22*H22 -> #DIV/0! | AG22: =(AC22-N22)/AC22 -> #DIV/0! | AH22: =IF(AG22<30%,"ERROR","OK") -> #DIV/0!
A23: =$A$13 -> TRUE | B23: =A23 -> TRUE | C23: =$C$13 -> Dólares | G23: =IFERROR(VLOOKUP(F23,Tabla_Proveedores_1,2,0)," ") | H23: 0 | I23: =IFERROR(VLOOKUP(G23,Proveedores!B:C,2,0)," ") | J23: 0 | L23: =K23*H23 -> 0 | M23: =IF(F23="Offiho", J23*0.55, IF(AND(F23<>"Sunon Inc",F23<>"Alma - Exterior",F23<>"Yabo - Hotelería",F23<>"OSJ - Medical",F23<>"Seezo - Home",F23<>"A&D -Home",F23<>"Encore Alfombras Hoteleria Asia",F23<>"Zhong Xian - Leds",F23<>"Tarkett Europa",F23<>"2tec2",F23<>"Balsan Europa",F23<>"Armstrong Pisos USA",F23<>"Tarkett USA",F23<>"Tarkett Brasil"),J23,IFERROR(IF(J582<=$AO$578,J23*2.14,IF(J582<=$AN$579,J23*1.8,IF(J582>$AN$580,J23*1.5))),J23))*1.1) -> 0 | N23: =M23*H23 -> 0 | O23: =IFERROR(VLOOKUP(G23,Proveedores!B:D,3,0)," ") | Q23: =VLOOKUP(E23,Tabla_Fletes,3,FALSE) -> #N/A | R23: =IF(P23="Centro",Q23,IF(P23="Norte",Q23*1.6,IF(P23="Occidente",Q23*1.2,IF(P23="Sur",Q23*2)))) -> FALSE | S23: =VLOOKUP(E23,Tabla_Instalacion,2,FALSE) -> #N/A | T23: =IF(P23="Centro",S23,IF(P23="Norte",S23*1.1,IF(P23="Occidente",S23*1.1,IF(P23="Sur",S23*1.1)))) -> FALSE | U23: =IF(F23="Offiho",0,R23+T23) -> 0 | V23: =IF(K23=0,U23/$H$573,U23*(K23/L23))*H23 -> #DIV/0! | W23: =IF(F23="Offiho",J23,IF(_xlfn.XLOOKUP(F23,Proveedores!A$2:A$50,Proveedores!E$2:E$50,"")="Nacional",(J23/0.5)+(V23*H23),((J23/0.3/0.5)+(V23*H23)))) -> #DIV/0! | X23: =(W23*H23) -> #DIV/0! | Y23: =IF(F23="Sunon Inc",$AJ$577,IF(F23="Alma - Exterior",$AJ$578,IF(F23="Yabo - Hotelería",$AJ$579,IF(F23="OSJ - Medical",$AJ$580,IF(F23="Seezo - Home",$AJ$581,IF(F23="A&D - Home",$AJ$582,IF(F23="Encore Alfombras Hoteleria Asia",$AJ$583,IF(F23="Zhong Xian - Leds",$AJ$584,IF(F23="Tarkett Europa",$AJ$585,IF(F23="2tec2",$AJ$586,IF(F23="Balsan Europa",$AJ$587,IF(F23="Armstrong Pisos USA",$AJ$588,IF(F23="Tarkett USA",$AJ$589,IF(F23="Tarkett Brasil",$AJ$590,IF(F23="Tarkett MX",$AJ$591,IF(F23="Jome",$AJ$592,IF(F23="Offiho",$AJ$593,IF(F23="Lumbro",$AJ$594,IF(F23="Sunon Mty",$AJ$595,IF(F23="Conceptos Sofas",$AJ$596,IF(F23="Lauco Sofas",$AJ$597,IF(F23="CR Global - Mesas Ajustables",$AJ$598,IF(F23="Vandesk",$AJ$599,IF(F23="Mamparas Tela",$AJ$600,IF(F23="Mampara Cristales",$AJ$601,IF(F23="Herrajes",$AJ$602,IF(F23="MetalWork",$AJ$603,IF(F23="Requiez",$AJ$604,IF(F23="Labenze",$AJ$605,IF(F23="Infinity",$AJ$606,IF(F23="Proveedor Externo",$AJ$607))))))))))))))))))))))))))))))) -> FALSE | Z23: 0 | AA23: =W23*Z23 -> #DIV/0! | AB23: =IF(Z23>Y23,"ERROR",(W23-AA23)) -> #DIV/0! | AC23: =AB23*H23 -> #DIV/0! | AD23: =IF(A24=TRUE,MAX(0,1-(AE23/W23)),"NA") -> #DIV/0! | AE23: =IF(A22=FALSE,"NO APLICA",AB23*1.2) -> #DIV/0! | AF23: =AE23*H23 -> #DIV/0! | AG23: =(AC23-N23)/AC23 -> #DIV/0! | AH23: =IF(AG23<30%,"ERROR","OK") -> #DIV/0!
A24: =$A$13 -> TRUE | B24: =A24 -> TRUE | C24: =$C$13 -> Dólares | G24: =IFERROR(VLOOKUP(F24,Tabla_Proveedores_1,2,0)," ") | H24: 0 | I24: =IFERROR(VLOOKUP(G24,Proveedores!B:C,2,0)," ") | J24: 0 | L24: =K24*H24 -> 0 | M24: =IF(F24="Offiho", J24*0.55, IF(AND(F24<>"Sunon Inc",F24<>"Alma - Exterior",F24<>"Yabo - Hotelería",F24<>"OSJ - Medical",F24<>"Seezo - Home",F24<>"A&D -Home",F24<>"Encore Alfombras Hoteleria Asia",F24<>"Zhong Xian - Leds",F24<>"Tarkett Europa",F24<>"2tec2",F24<>"Balsan Europa",F24<>"Armstrong Pisos USA",F24<>"Tarkett USA",F24<>"Tarkett Brasil"),J24,IFERROR(IF(J583<=$AO$578,J24*2.14,IF(J583<=$AN$579,J24*1.8,IF(J583>$AN$580,J24*1.5))),J24))*1.1) -> 0 | N24: =M24*H24 -> 0 | O24: =IFERROR(VLOOKUP(G24,Proveedores!B:D,3,0)," ") | Q24: =VLOOKUP(E24,Tabla_Fletes,3,FALSE) -> #N/A | R24: =IF(P24="Centro",Q24,IF(P24="Norte",Q24*1.6,IF(P24="Occidente",Q24*1.2,IF(P24="Sur",Q24*2)))) -> FALSE | S24: =VLOOKUP(E24,Tabla_Instalacion,2,FALSE) -> #N/A | T24: =IF(P24="Centro",S24,IF(P24="Norte",S24*1.1,IF(P24="Occidente",S24*1.1,IF(P24="Sur",S24*1.1)))) -> FALSE | U24: =IF(F24="Offiho",0,R24+T24) -> 0 | V24: =IF(K24=0,U24/$H$573,U24*(K24/L24))*H24 -> #DIV/0! | W24: =IF(F24="Offiho",J24,IF(_xlfn.XLOOKUP(F24,Proveedores!A$2:A$50,Proveedores!E$2:E$50,"")="Nacional",(J24/0.5)+(V24*H24),((J24/0.3/0.5)+(V24*H24)))) -> #DIV/0! | X24: =(W24*H24) -> #DIV/0! | Y24: =IF(F24="Sunon Inc",$AJ$577,IF(F24="Alma - Exterior",$AJ$578,IF(F24="Yabo - Hotelería",$AJ$579,IF(F24="OSJ - Medical",$AJ$580,IF(F24="Seezo - Home",$AJ$581,IF(F24="A&D - Home",$AJ$582,IF(F24="Encore Alfombras Hoteleria Asia",$AJ$583,IF(F24="Zhong Xian - Leds",$AJ$584,IF(F24="Tarkett Europa",$AJ$585,IF(F24="2tec2",$AJ$586,IF(F24="Balsan Europa",$AJ$587,IF(F24="Armstrong Pisos USA",$AJ$588,IF(F24="Tarkett USA",$AJ$589,IF(F24="Tarkett Brasil",$AJ$590,IF(F24="Tarkett MX",$AJ$591,IF(F24="Jome",$AJ$592,IF(F24="Offiho",$AJ$593,IF(F24="Lumbro",$AJ$594,IF(F24="Sunon Mty",$AJ$595,IF(F24="Conceptos Sofas",$AJ$596,IF(F24="Lauco Sofas",$AJ$597,IF(F24="CR Global - Mesas Ajustables",$AJ$598,IF(F24="Vandesk",$AJ$599,IF(F24="Mamparas Tela",$AJ$600,IF(F24="Mampara Cristales",$AJ$601,IF(F24="Herrajes",$AJ$602,IF(F24="MetalWork",$AJ$603,IF(F24="Requiez",$AJ$604,IF(F24="Labenze",$AJ$605,IF(F24="Infinity",$AJ$606,IF(F24="Proveedor Externo",$AJ$607))))))))))))))))))))))))))))))) -> FALSE | Z24: 0 | AA24: =W24*Z24 -> #DIV/0! | AB24: =IF(Z24>Y24,"ERROR",(W24-AA24)) -> #DIV/0! | AC24: =AB24*H24 -> #DIV/0! | AD24: =IF(A25=TRUE,MAX(0,1-(AE24/W24)),"NA") -> #DIV/0! | AE24: =IF(A23=FALSE,"NO APLICA",AB24*1.2) -> #DIV/0! | AF24: =AE24*H24 -> #DIV/0! | AG24: =(AC24-N24)/AC24 -> #DIV/0! | AH24: =IF(AG24<30%,"ERROR","OK") -> #DIV/0!
A25: =$A$13 -> TRUE | B25: =A25 -> TRUE | C25: =$C$13 -> Dólares | G25: =IFERROR(VLOOKUP(F25,Tabla_Proveedores_1,2,0)," ") | H25: 0 | I25: =IFERROR(VLOOKUP(G25,Proveedores!B:C,2,0)," ") | J25: 0 | L25: =K25*H25 -> 0 | M25: =IF(F25="Offiho", J25*0.55, IF(AND(F25<>"Sunon Inc",F25<>"Alma - Exterior",F25<>"Yabo - Hotelería",F25<>"OSJ - Medical",F25<>"Seezo - Home",F25<>"A&D -Home",F25<>"Encore Alfombras Hoteleria Asia",F25<>"Zhong Xian - Leds",F25<>"Tarkett Europa",F25<>"2tec2",F25<>"Balsan Europa",F25<>"Armstrong Pisos USA",F25<>"Tarkett USA",F25<>"Tarkett Brasil"),J25,IFERROR(IF(J584<=$AO$578,J25*2.14,IF(J584<=$AN$579,J25*1.8,IF(J584>$AN$580,J25*1.5))),J25))*1.1) -> 0 | N25: =M25*H25 -> 0 | O25: =IFERROR(VLOOKUP(G25,Proveedores!B:D,3,0)," ") | Q25: =VLOOKUP(E25,Tabla_Fletes,3,FALSE) -> #N/A | R25: =IF(P25="Centro",Q25,IF(P25="Norte",Q25*1.6,IF(P25="Occidente",Q25*1.2,IF(P25="Sur",Q25*2)))) -> FALSE | S25: =VLOOKUP(E25,Tabla_Instalacion,2,FALSE) -> #N/A | T25: =IF(P25="Centro",S25,IF(P25="Norte",S25*1.1,IF(P25="Occidente",S25*1.1,IF(P25="Sur",S25*1.1)))) -> FALSE | U25: =IF(F25="Offiho",0,R25+T25) -> 0 | V25: =IF(K25=0,U25/$H$573,U25*(K25/L25))*H25 -> #DIV/0! | W25: =IF(F25="Offiho",J25,IF(_xlfn.XLOOKUP(F25,Proveedores!A$2:A$50,Proveedores!E$2:E$50,"")="Nacional",(J25/0.5)+(V25*H25),((J25/0.3/0.5)+(V25*H25)))) -> #DIV/0! | X25: =(W25*H25) -> #DIV/0! | Y25: =IF(F25="Sunon Inc",$AJ$577,IF(F25="Alma - Exterior",$AJ$578,IF(F25="Yabo - Hotelería",$AJ$579,IF(F25="OSJ - Medical",$AJ$580,IF(F25="Seezo - Home",$AJ$581,IF(F25="A&D - Home",$AJ$582,IF(F25="Encore Alfombras Hoteleria Asia",$AJ$583,IF(F25="Zhong Xian - Leds",$AJ$584,IF(F25="Tarkett Europa",$AJ$585,IF(F25="2tec2",$AJ$586,IF(F25="Balsan Europa",$AJ$587,IF(F25="Armstrong Pisos USA",$AJ$588,IF(F25="Tarkett USA",$AJ$589,IF(F25="Tarkett Brasil",$AJ$590,IF(F25="Tarkett MX",$AJ$591,IF(F25="Jome",$AJ$592,IF(F25="Offiho",$AJ$593,IF(F25="Lumbro",$AJ$594,IF(F25="Sunon Mty",$AJ$595,IF(F25="Conceptos Sofas",$AJ$596,IF(F25="Lauco Sofas",$AJ$597,IF(F25="CR Global - Mesas Ajustables",$AJ$598,IF(F25="Vandesk",$AJ$599,IF(F25="Mamparas Tela",$AJ$600,IF(F25="Mampara Cristales",$AJ$601,IF(F25="Herrajes",$AJ$602,IF(F25="MetalWork",$AJ$603,IF(F25="Requiez",$AJ$604,IF(F25="Labenze",$AJ$605,IF(F25="Infinity",$AJ$606,IF(F25="Proveedor Externo",$AJ$607))))))))))))))))))))))))))))))) -> FALSE | Z25: 0 | AA25: =W25*Z25 -> #DIV/0! | AB25: =IF(Z25>Y25,"ERROR",(W25-AA25)) -> #DIV/0! | AC25: =AB25*H25 -> #DIV/0! | AD25: =IF(A26=TRUE,MAX(0,1-(AE25/W25)),"NA") -> #DIV/0! | AE25: =IF(A24=FALSE,"NO APLICA",AB25*1.2) -> #DIV/0! | AF25: =AE25*H25 -> #DIV/0! | AG25: =(AC25-N25)/AC25 -> #DIV/0! | AH25: =IF(AG25<30%,"ERROR","OK") -> #DIV/0!
A26: =$A$13 -> TRUE | B26: =A26 -> TRUE | C26: =$C$13 -> Dólares | G26: =IFERROR(VLOOKUP(F26,Tabla_Proveedores_1,2,0)," ") | H26: 0 | I26: =IFERROR(VLOOKUP(G26,Proveedores!B:C,2,0)," ") | J26: 0 | L26: =K26*H26 -> 0 | M26: =IF(F26="Offiho", J26*0.55, IF(AND(F26<>"Sunon Inc",F26<>"Alma - Exterior",F26<>"Yabo - Hotelería",F26<>"OSJ - Medical",F26<>"Seezo - Home",F26<>"A&D -Home",F26<>"Encore Alfombras Hoteleria Asia",F26<>"Zhong Xian - Leds",F26<>"Tarkett Europa",F26<>"2tec2",F26<>"Balsan Europa",F26<>"Armstrong Pisos USA",F26<>"Tarkett USA",F26<>"Tarkett Brasil"),J26,IFERROR(IF(J585<=$AO$578,J26*2.14,IF(J585<=$AN$579,J26*1.8,IF(J585>$AN$580,J26*1.5))),J26))*1.1) -> 0 | N26: =M26*H26 -> 0 | O26: =IFERROR(VLOOKUP(G26,Proveedores!B:D,3,0)," ") | Q26: =VLOOKUP(E26,Tabla_Fletes,3,FALSE) -> #N/A | R26: =IF(P26="Centro",Q26,IF(P26="Norte",Q26*1.6,IF(P26="Occidente",Q26*1.2,IF(P26="Sur",Q26*2)))) -> FALSE | S26: =VLOOKUP(E26,Tabla_Instalacion,2,FALSE) -> #N/A | T26: =IF(P26="Centro",S26,IF(P26="Norte",S26*1.1,IF(P26="Occidente",S26*1.1,IF(P26="Sur",S26*1.1)))) -> FALSE | U26: =IF(F26="Offiho",0,R26+T26) -> 0 | V26: =IF(K26=0,U26/$H$573,U26*(K26/L26))*H26 -> #DIV/0! | W26: =IF(F26="Offiho",J26,IF(_xlfn.XLOOKUP(F26,Proveedores!A$2:A$50,Proveedores!E$2:E$50,"")="Nacional",(J26/0.5)+(V26*H26),((J26/0.3/0.5)+(V26*H26)))) -> #DIV/0! | X26: =(W26*H26) -> #DIV/0! | Y26: =IF(F26="Sunon Inc",$AJ$577,IF(F26="Alma - Exterior",$AJ$578,IF(F26="Yabo - Hotelería",$AJ$579,IF(F26="OSJ - Medical",$AJ$580,IF(F26="Seezo - Home",$AJ$581,IF(F26="A&D - Home",$AJ$582,IF(F26="Encore Alfombras Hoteleria Asia",$AJ$583,IF(F26="Zhong Xian - Leds",$AJ$584,IF(F26="Tarkett Europa",$AJ$585,IF(F26="2tec2",$AJ$586,IF(F26="Balsan Europa",$AJ$587,IF(F26="Armstrong Pisos USA",$AJ$588,IF(F26="Tarkett USA",$AJ$589,IF(F26="Tarkett Brasil",$AJ$590,IF(F26="Tarkett MX",$AJ$591,IF(F26="Jome",$AJ$592,IF(F26="Offiho",$AJ$593,IF(F26="Lumbro",$AJ$594,IF(F26="Sunon Mty",$AJ$595,IF(F26="Conceptos Sofas",$AJ$596,IF(F26="Lauco Sofas",$AJ$597,IF(F26="CR Global - Mesas Ajustables",$AJ$598,IF(F26="Vandesk",$AJ$599,IF(F26="Mamparas Tela",$AJ$600,IF(F26="Mampara Cristales",$AJ$601,IF(F26="Herrajes",$AJ$602,IF(F26="MetalWork",$AJ$603,IF(F26="Requiez",$AJ$604,IF(F26="Labenze",$AJ$605,IF(F26="Infinity",$AJ$606,IF(F26="Proveedor Externo",$AJ$607))))))))))))))))))))))))))))))) -> FALSE | Z26: 0 | AA26: =W26*Z26 -> #DIV/0! | AB26: =IF(Z26>Y26,"ERROR",(W26-AA26)) -> #DIV/0! | AC26: =AB26*H26 -> #DIV/0! | AD26: =IF(A27=TRUE,MAX(0,1-(AE26/W26)),"NA") -> #DIV/0! | AE26: =IF(A25=FALSE,"NO APLICA",AB26*1.2) -> #DIV/0! | AF26: =AE26*H26 -> #DIV/0! | AG26: =(AC26-N26)/AC26 -> #DIV/0! | AH26: =IF(AG26<30%,"ERROR","OK") -> #DIV/0!
A27: =$A$13 -> TRUE | B27: =A27 -> TRUE | C27: =$C$13 -> Dólares | G27: =IFERROR(VLOOKUP(F27,Tabla_Proveedores_1,2,0)," ") | H27: 0 | I27: =IFERROR(VLOOKUP(G27,Proveedores!B:C,2,0)," ") | J27: 0 | L27: =K27*H27 -> 0 | M27: =IF(F27="Offiho", J27*0.55, IF(AND(F27<>"Sunon Inc",F27<>"Alma - Exterior",F27<>"Yabo - Hotelería",F27<>"OSJ - Medical",F27<>"Seezo - Home",F27<>"A&D -Home",F27<>"Encore Alfombras Hoteleria Asia",F27<>"Zhong Xian - Leds",F27<>"Tarkett Europa",F27<>"2tec2",F27<>"Balsan Europa",F27<>"Armstrong Pisos USA",F27<>"Tarkett USA",F27<>"Tarkett Brasil"),J27,IFERROR(IF(J586<=$AO$578,J27*2.14,IF(J586<=$AN$579,J27*1.8,IF(J586>$AN$580,J27*1.5))),J27))*1.1) -> 0 | N27: =M27*H27 -> 0 | O27: =IFERROR(VLOOKUP(G27,Proveedores!B:D,3,0)," ") | Q27: =VLOOKUP(E27,Tabla_Fletes,3,FALSE) -> #N/A | R27: =IF(P27="Centro",Q27,IF(P27="Norte",Q27*1.6,IF(P27="Occidente",Q27*1.2,IF(P27="Sur",Q27*2)))) -> FALSE | S27: =VLOOKUP(E27,Tabla_Instalacion,2,FALSE) -> #N/A | T27: =IF(P27="Centro",S27,IF(P27="Norte",S27*1.1,IF(P27="Occidente",S27*1.1,IF(P27="Sur",S27*1.1)))) -> FALSE | U27: =IF(F27="Offiho",0,R27+T27) -> 0 | V27: =IF(K27=0,U27/$H$573,U27*(K27/L27))*H27 -> #DIV/0! | W27: =IF(F27="Offiho",J27,IF(_xlfn.XLOOKUP(F27,Proveedores!A$2:A$50,Proveedores!E$2:E$50,"")="Nacional",(J27/0.5)+(V27*H27),((J27/0.3/0.5)+(V27*H27)))) -> #DIV/0! | X27: =(W27*H27) -> #DIV/0! | Y27: =IF(F27="Sunon Inc",$AJ$577,IF(F27="Alma - Exterior",$AJ$578,IF(F27="Yabo - Hotelería",$AJ$579,IF(F27="OSJ - Medical",$AJ$580,IF(F27="Seezo - Home",$AJ$581,IF(F27="A&D - Home",$AJ$582,IF(F27="Encore Alfombras Hoteleria Asia",$AJ$583,IF(F27="Zhong Xian - Leds",$AJ$584,IF(F27="Tarkett Europa",$AJ$585,IF(F27="2tec2",$AJ$586,IF(F27="Balsan Europa",$AJ$587,IF(F27="Armstrong Pisos USA",$AJ$588,IF(F27="Tarkett USA",$AJ$589,IF(F27="Tarkett Brasil",$AJ$590,IF(F27="Tarkett MX",$AJ$591,IF(F27="Jome",$AJ$592,IF(F27="Offiho",$AJ$593,IF(F27="Lumbro",$AJ$594,IF(F27="Sunon Mty",$AJ$595,IF(F27="Conceptos Sofas",$AJ$596,IF(F27="Lauco Sofas",$AJ$597,IF(F27="CR Global - Mesas Ajustables",$AJ$598,IF(F27="Vandesk",$AJ$599,IF(F27="Mamparas Tela",$AJ$600,IF(F27="Mampara Cristales",$AJ$601,IF(F27="Herrajes",$AJ$602,IF(F27="MetalWork",$AJ$603,IF(F27="Requiez",$AJ$604,IF(F27="Labenze",$AJ$605,IF(F27="Infinity",$AJ$606,IF(F27="Proveedor Externo",$AJ$607))))))))))))))))))))))))))))))) -> FALSE | Z27: 0 | AA27: =W27*Z27 -> #DIV/0! | AB27: =IF(Z27>Y27,"ERROR",(W27-AA27)) -> #DIV/0! | AC27: =AB27*H27 -> #DIV/0! | AD27: =IF(A28=TRUE,MAX(0,1-(AE27/W27)),"NA") -> #DIV/0! | AE27: =IF(A26=FALSE,"NO APLICA",AB27*1.2) -> #DIV/0! | AF27: =AE27*H27 -> #DIV/0! | AG27: =(AC27-N27)/AC27 -> #DIV/0! | AH27: =IF(AG27<30%,"ERROR","OK") -> #DIV/0!
A28: =$A$13 -> TRUE | B28: =A28 -> TRUE | C28: =$C$13 -> Dólares | G28: =IFERROR(VLOOKUP(F28,Tabla_Proveedores_1,2,0)," ") | H28: 0 | I28: =IFERROR(VLOOKUP(G28,Proveedores!B:C,2,0)," ") | J28: 0 | L28: =K28*H28 -> 0 | M28: =IF(F28="Offiho", J28*0.55, IF(AND(F28<>"Sunon Inc",F28<>"Alma - Exterior",F28<>"Yabo - Hotelería",F28<>"OSJ - Medical",F28<>"Seezo - Home",F28<>"A&D -Home",F28<>"Encore Alfombras Hoteleria Asia",F28<>"Zhong Xian - Leds",F28<>"Tarkett Europa",F28<>"2tec2",F28<>"Balsan Europa",F28<>"Armstrong Pisos USA",F28<>"Tarkett USA",F28<>"Tarkett Brasil"),J28,IFERROR(IF(J587<=$AO$578,J28*2.14,IF(J587<=$AN$579,J28*1.8,IF(J587>$AN$580,J28*1.5))),J28))*1.1) -> 0 | N28: =M28*H28 -> 0 | O28: =IFERROR(VLOOKUP(G28,Proveedores!B:D,3,0)," ") | Q28: =VLOOKUP(E28,Tabla_Fletes,3,FALSE) -> #N/A | R28: =IF(P28="Centro",Q28,IF(P28="Norte",Q28*1.6,IF(P28="Occidente",Q28*1.2,IF(P28="Sur",Q28*2)))) -> FALSE | S28: =VLOOKUP(E28,Tabla_Instalacion,2,FALSE) -> #N/A | T28: =IF(P28="Centro",S28,IF(P28="Norte",S28*1.1,IF(P28="Occidente",S28*1.1,IF(P28="Sur",S28*1.1)))) -> FALSE | U28: =IF(F28="Offiho",0,R28+T28) -> 0 | V28: =IF(K28=0,U28/$H$573,U28*(K28/L28))*H28 -> #DIV/0! | W28: =IF(F28="Offiho",J28,IF(_xlfn.XLOOKUP(F28,Proveedores!A$2:A$50,Proveedores!E$2:E$50,"")="Nacional",(J28/0.5)+(V28*H28),((J28/0.3/0.5)+(V28*H28)))) -> #DIV/0! | X28: =(W28*H28) -> #DIV/0! | Y28: =IF(F28="Sunon Inc",$AJ$577,IF(F28="Alma - Exterior",$AJ$578,IF(F28="Yabo - Hotelería",$AJ$579,IF(F28="OSJ - Medical",$AJ$580,IF(F28="Seezo - Home",$AJ$581,IF(F28="A&D - Home",$AJ$582,IF(F28="Encore Alfombras Hoteleria Asia",$AJ$583,IF(F28="Zhong Xian - Leds",$AJ$584,IF(F28="Tarkett Europa",$AJ$585,IF(F28="2tec2",$AJ$586,IF(F28="Balsan Europa",$AJ$587,IF(F28="Armstrong Pisos USA",$AJ$588,IF(F28="Tarkett USA",$AJ$589,IF(F28="Tarkett Brasil",$AJ$590,IF(F28="Tarkett MX",$AJ$591,IF(F28="Jome",$AJ$592,IF(F28="Offiho",$AJ$593,IF(F28="Lumbro",$AJ$594,IF(F28="Sunon Mty",$AJ$595,IF(F28="Conceptos Sofas",$AJ$596,IF(F28="Lauco Sofas",$AJ$597,IF(F28="CR Global - Mesas Ajustables",$AJ$598,IF(F28="Vandesk",$AJ$599,IF(F28="Mamparas Tela",$AJ$600,IF(F28="Mampara Cristales",$AJ$601,IF(F28="Herrajes",$AJ$602,IF(F28="MetalWork",$AJ$603,IF(F28="Requiez",$AJ$604,IF(F28="Labenze",$AJ$605,IF(F28="Infinity",$AJ$606,IF(F28="Proveedor Externo",$AJ$607))))))))))))))))))))))))))))))) -> FALSE | Z28: 0 | AA28: =W28*Z28 -> #DIV/0! | AB28: =IF(Z28>Y28,"ERROR",(W28-AA28)) -> #DIV/0! | AC28: =AB28*H28 -> #DIV/0! | AD28: =IF(A29=TRUE,MAX(0,1-(AE28/W28)),"NA") -> #DIV/0! | AE28: =IF(A27=FALSE,"NO APLICA",AB28*1.2) -> #DIV/0! | AF28: =AE28*H28 -> #DIV/0! | AG28: =(AC28-N28)/AC28 -> #DIV/0! | AH28: =IF(AG28<30%,"ERROR","OK") -> #DIV/0!
A29: =$A$13 -> TRUE | B29: =A29 -> TRUE | C29: =$C$13 -> Dólares | G29: =IFERROR(VLOOKUP(F29,Tabla_Proveedores_1,2,0)," ") | H29: 0 | I29: =IFERROR(VLOOKUP(G29,Proveedores!B:C,2,0)," ") | J29: 0 | L29: =K29*H29 -> 0 | M29: =IF(F29="Offiho", J29*0.55, IF(AND(F29<>"Sunon Inc",F29<>"Alma - Exterior",F29<>"Yabo - Hotelería",F29<>"OSJ - Medical",F29<>"Seezo - Home",F29<>"A&D -Home",F29<>"Encore Alfombras Hoteleria Asia",F29<>"Zhong Xian - Leds",F29<>"Tarkett Europa",F29<>"2tec2",F29<>"Balsan Europa",F29<>"Armstrong Pisos USA",F29<>"Tarkett USA",F29<>"Tarkett Brasil"),J29,IFERROR(IF(J588<=$AO$578,J29*2.14,IF(J588<=$AN$579,J29*1.8,IF(J588>$AN$580,J29*1.5))),J29))*1.1) -> 0 | N29: =M29*H29 -> 0 | O29: =IFERROR(VLOOKUP(G29,Proveedores!B:D,3,0)," ") | Q29: =VLOOKUP(E29,Tabla_Fletes,3,FALSE) -> #N/A | R29: =IF(P29="Centro",Q29,IF(P29="Norte",Q29*1.6,IF(P29="Occidente",Q29*1.2,IF(P29="Sur",Q29*2)))) -> FALSE | S29: =VLOOKUP(E29,Tabla_Instalacion,2,FALSE) -> #N/A | T29: =IF(P29="Centro",S29,IF(P29="Norte",S29*1.1,IF(P29="Occidente",S29*1.1,IF(P29="Sur",S29*1.1)))) -> FALSE | U29: =IF(F29="Offiho",0,R29+T29) -> 0 | V29: =IF(K29=0,U29/$H$573,U29*(K29/L29))*H29 -> #DIV/0! | W29: =IF(F29="Offiho",J29,IF(_xlfn.XLOOKUP(F29,Proveedores!A$2:A$50,Proveedores!E$2:E$50,"")="Nacional",(J29/0.5)+(V29*H29),((J29/0.3/0.5)+(V29*H29)))) -> #DIV/0! | X29: =(W29*H29) -> #DIV/0! | Y29: =IF(F29="Sunon Inc",$AJ$577,IF(F29="Alma - Exterior",$AJ$578,IF(F29="Yabo - Hotelería",$AJ$579,IF(F29="OSJ - Medical",$AJ$580,IF(F29="Seezo - Home",$AJ$581,IF(F29="A&D - Home",$AJ$582,IF(F29="Encore Alfombras Hoteleria Asia",$AJ$583,IF(F29="Zhong Xian - Leds",$AJ$584,IF(F29="Tarkett Europa",$AJ$585,IF(F29="2tec2",$AJ$586,IF(F29="Balsan Europa",$AJ$587,IF(F29="Armstrong Pisos USA",$AJ$588,IF(F29="Tarkett USA",$AJ$589,IF(F29="Tarkett Brasil",$AJ$590,IF(F29="Tarkett MX",$AJ$591,IF(F29="Jome",$AJ$592,IF(F29="Offiho",$AJ$593,IF(F29="Lumbro",$AJ$594,IF(F29="Sunon Mty",$AJ$595,IF(F29="Conceptos Sofas",$AJ$596,IF(F29="Lauco Sofas",$AJ$597,IF(F29="CR Global - Mesas Ajustables",$AJ$598,IF(F29="Vandesk",$AJ$599,IF(F29="Mamparas Tela",$AJ$600,IF(F29="Mampara Cristales",$AJ$601,IF(F29="Herrajes",$AJ$602,IF(F29="MetalWork",$AJ$603,IF(F29="Requiez",$AJ$604,IF(F29="Labenze",$AJ$605,IF(F29="Infinity",$AJ$606,IF(F29="Proveedor Externo",$AJ$607))))))))))))))))))))))))))))))) -> FALSE | Z29: 0 | AA29: =W29*Z29 -> #DIV/0! | AB29: =IF(Z29>Y29,"ERROR",(W29-AA29)) -> #DIV/0! | AC29: =AB29*H29 -> #DIV/0! | AD29: =IF(A30=TRUE,MAX(0,1-(AE29/W29)),"NA") -> #DIV/0! | AE29: =IF(A28=FALSE,"NO APLICA",AB29*1.2) -> #DIV/0! | AF29: =AE29*H29 -> #DIV/0! | AG29: =(AC29-N29)/AC29 -> #DIV/0! | AH29: =IF(AG29<30%,"ERROR","OK") -> #DIV/0!
A30: =$A$13 -> TRUE | B30: =A30 -> TRUE | C30: =$C$13 -> Dólares | G30: =IFERROR(VLOOKUP(F30,Tabla_Proveedores_1,2,0)," ") | H30: 0 | I30: =IFERROR(VLOOKUP(G30,Proveedores!B:C,2,0)," ") | J30: 0 | L30: =K30*H30 -> 0 | M30: =IF(F30="Offiho", J30*0.55, IF(AND(F30<>"Sunon Inc",F30<>"Alma - Exterior",F30<>"Yabo - Hotelería",F30<>"OSJ - Medical",F30<>"Seezo - Home",F30<>"A&D -Home",F30<>"Encore Alfombras Hoteleria Asia",F30<>"Zhong Xian - Leds",F30<>"Tarkett Europa",F30<>"2tec2",F30<>"Balsan Europa",F30<>"Armstrong Pisos USA",F30<>"Tarkett USA",F30<>"Tarkett Brasil"),J30,IFERROR(IF(J589<=$AO$578,J30*2.14,IF(J589<=$AN$579,J30*1.8,IF(J589>$AN$580,J30*1.5))),J30))*1.1) -> 0 | N30: =M30*H30 -> 0 | O30: =IFERROR(VLOOKUP(G30,Proveedores!B:D,3,0)," ") | Q30: =VLOOKUP(E30,Tabla_Fletes,3,FALSE) -> #N/A | R30: =IF(P30="Centro",Q30,IF(P30="Norte",Q30*1.6,IF(P30="Occidente",Q30*1.2,IF(P30="Sur",Q30*2)))) -> FALSE | S30: =VLOOKUP(E30,Tabla_Instalacion,2,FALSE) -> #N/A | T30: =IF(P30="Centro",S30,IF(P30="Norte",S30*1.1,IF(P30="Occidente",S30*1.1,IF(P30="Sur",S30*1.1)))) -> FALSE | U30: =IF(F30="Offiho",0,R30+T30) -> 0 | V30: =IF(K30=0,U30/$H$573,U30*(K30/L30))*H30 -> #DIV/0! | W30: =IF(F30="Offiho",J30,IF(_xlfn.XLOOKUP(F30,Proveedores!A$2:A$50,Proveedores!E$2:E$50,"")="Nacional",(J30/0.5)+(V30*H30),((J30/0.3/0.5)+(V30*H30)))) -> #DIV/0! | X30: =(W30*H30) -> #DIV/0! | Y30: =IF(F30="Sunon Inc",$AJ$577,IF(F30="Alma - Exterior",$AJ$578,IF(F30="Yabo - Hotelería",$AJ$579,IF(F30="OSJ - Medical",$AJ$580,IF(F30="Seezo - Home",$AJ$581,IF(F30="A&D - Home",$AJ$582,IF(F30="Encore Alfombras Hoteleria Asia",$AJ$583,IF(F30="Zhong Xian - Leds",$AJ$584,IF(F30="Tarkett Europa",$AJ$585,IF(F30="2tec2",$AJ$586,IF(F30="Balsan Europa",$AJ$587,IF(F30="Armstrong Pisos USA",$AJ$588,IF(F30="Tarkett USA",$AJ$589,IF(F30="Tarkett Brasil",$AJ$590,IF(F30="Tarkett MX",$AJ$591,IF(F30="Jome",$AJ$592,IF(F30="Offiho",$AJ$593,IF(F30="Lumbro",$AJ$594,IF(F30="Sunon Mty",$AJ$595,IF(F30="Conceptos Sofas",$AJ$596,IF(F30="Lauco Sofas",$AJ$597,IF(F30="CR Global - Mesas Ajustables",$AJ$598,IF(F30="Vandesk",$AJ$599,IF(F30="Mamparas Tela",$AJ$600,IF(F30="Mampara Cristales",$AJ$601,IF(F30="Herrajes",$AJ$602,IF(F30="MetalWork",$AJ$603,IF(F30="Requiez",$AJ$604,IF(F30="Labenze",$AJ$605,IF(F30="Infinity",$AJ$606,IF(F30="Proveedor Externo",$AJ$607))))))))))))))))))))))))))))))) -> FALSE | Z30: 0 | AA30: =W30*Z30 -> #DIV/0! | AB30: =IF(Z30>Y30,"ERROR",(W30-AA30)) -> #DIV/0! | AC30: =AB30*H30 -> #DIV/0! | AD30: =IF(A31=TRUE,MAX(0,1-(AE30/W30)),"NA") -> #DIV/0! | AE30: =IF(A29=FALSE,"NO APLICA",AB30*1.2) -> #DIV/0! | AF30: =AE30*H30 -> #DIV/0! | AG30: =(AC30-N30)/AC30 -> #DIV/0! | AH30: =IF(AG30<30%,"ERROR","OK") -> #DIV/0!
A31: =$A$13 -> TRUE | B31: =A31 -> TRUE | C31: =$C$13 -> Dólares | G31: =IFERROR(VLOOKUP(F31,Tabla_Proveedores_1,2,0)," ") | H31: 0 | I31: =IFERROR(VLOOKUP(G31,Proveedores!B:C,2,0)," ") | J31: 0 | L31: =K31*H31 -> 0 | M31: =IF(F31="Offiho", J31*0.55, IF(AND(F31<>"Sunon Inc",F31<>"Alma - Exterior",F31<>"Yabo - Hotelería",F31<>"OSJ - Medical",F31<>"Seezo - Home",F31<>"A&D -Home",F31<>"Encore Alfombras Hoteleria Asia",F31<>"Zhong Xian - Leds",F31<>"Tarkett Europa",F31<>"2tec2",F31<>"Balsan Europa",F31<>"Armstrong Pisos USA",F31<>"Tarkett USA",F31<>"Tarkett Brasil"),J31,IFERROR(IF(J590<=$AO$578,J31*2.14,IF(J590<=$AN$579,J31*1.8,IF(J590>$AN$580,J31*1.5))),J31))*1.1) -> 0 | N31: =M31*H31 -> 0 | O31: =IFERROR(VLOOKUP(G31,Proveedores!B:D,3,0)," ") | Q31: =VLOOKUP(E31,Tabla_Fletes,3,FALSE) -> #N/A | R31: =IF(P31="Centro",Q31,IF(P31="Norte",Q31*1.6,IF(P31="Occidente",Q31*1.2,IF(P31="Sur",Q31*2)))) -> FALSE | S31: =VLOOKUP(E31,Tabla_Instalacion,2,FALSE) -> #N/A | T31: =IF(P31="Centro",S31,IF(P31="Norte",S31*1.1,IF(P31="Occidente",S31*1.1,IF(P31="Sur",S31*1.1)))) -> FALSE | U31: =IF(F31="Offiho",0,R31+T31) -> 0 | V31: =IF(K31=0,U31/$H$573,U31*(K31/L31))*H31 -> #DIV/0! | W31: =IF(F31="Offiho",J31,IF(_xlfn.XLOOKUP(F31,Proveedores!A$2:A$50,Proveedores!E$2:E$50,"")="Nacional",(J31/0.5)+(V31*H31),((J31/0.3/0.5)+(V31*H31)))) -> #DIV/0! | X31: =(W31*H31) -> #DIV/0! | Y31: =IF(F31="Sunon Inc",$AJ$577,IF(F31="Alma - Exterior",$AJ$578,IF(F31="Yabo - Hotelería",$AJ$579,IF(F31="OSJ - Medical",$AJ$580,IF(F31="Seezo - Home",$AJ$581,IF(F31="A&D - Home",$AJ$582,IF(F31="Encore Alfombras Hoteleria Asia",$AJ$583,IF(F31="Zhong Xian - Leds",$AJ$584,IF(F31="Tarkett Europa",$AJ$585,IF(F31="2tec2",$AJ$586,IF(F31="Balsan Europa",$AJ$587,IF(F31="Armstrong Pisos USA",$AJ$588,IF(F31="Tarkett USA",$AJ$589,IF(F31="Tarkett Brasil",$AJ$590,IF(F31="Tarkett MX",$AJ$591,IF(F31="Jome",$AJ$592,IF(F31="Offiho",$AJ$593,IF(F31="Lumbro",$AJ$594,IF(F31="Sunon Mty",$AJ$595,IF(F31="Conceptos Sofas",$AJ$596,IF(F31="Lauco Sofas",$AJ$597,IF(F31="CR Global - Mesas Ajustables",$AJ$598,IF(F31="Vandesk",$AJ$599,IF(F31="Mamparas Tela",$AJ$600,IF(F31="Mampara Cristales",$AJ$601,IF(F31="Herrajes",$AJ$602,IF(F31="MetalWork",$AJ$603,IF(F31="Requiez",$AJ$604,IF(F31="Labenze",$AJ$605,IF(F31="Infinity",$AJ$606,IF(F31="Proveedor Externo",$AJ$607))))))))))))))))))))))))))))))) -> FALSE | Z31: 0 | AA31: =W31*Z31 -> #DIV/0! | AB31: =IF(Z31>Y31,"ERROR",(W31-AA31)) -> #DIV/0! | AC31: =AB31*H31 -> #DIV/0! | AD31: =IF(A32=TRUE,MAX(0,1-(AE31/W31)),"NA") -> #DIV/0! | AE31: =IF(A30=FALSE,"NO APLICA",AB31*1.2) -> #DIV/0! | AF31: =AE31*H31 -> #DIV/0! | AG31: =(AC31-N31)/AC31 -> #DIV/0! | AH31: =IF(AG31<30%,"ERROR","OK") -> #DIV/0!
